<?xml version="1.0"?>
<robot name="dw_robot" xmlns:xacro="http://www.ros.org/wiki/xacro">

  <!-- ========================= -->
  <!-- Robot parameters -->
  <!-- ========================= -->

  <xacro:property name="base_length" value="0.45"/>
  <xacro:property name="base_width" value="0.32"/>
  <xacro:property name="base_height" value="0.12"/>

  <xacro:property name="wheel_radius" value="0.075"/>
  <xacro:property name="wheel_width" value="0.04"/>
  <xacro:property name="wheel_separation" value="0.35"/>

  <xacro:property name="base_z" value="${wheel_radius + base_height / 2.0}"/>

  <!-- ========================= -->
  <!-- Materials -->
  <!-- ========================= -->

  <material name="gray">
    <color rgba="0.5 0.5 0.5 1.0"/>
  </material>

  <material name="black">
    <color rgba="0.02 0.02 0.02 1.0"/>
  </material>

  <material name="blue">
    <color rgba="0.1 0.2 0.8 1.0"/>
  </material>

  <material name="red">
    <color rgba="0.8 0.1 0.1 1.0"/>
  </material>

  <!-- ========================= -->
  <!-- base_footprint -->
  <!-- ========================= -->

  <link name="base_footprint"/>

  <!-- ========================= -->
  <!-- base_link -->
  <!-- ========================= -->

  <joint name="base_footprint_to_base_link" type="fixed">
    <parent link="base_footprint"/>
    <child link="base_link"/>
    <origin xyz="0 0 ${base_z}" rpy="0 0 0"/>
  </joint>

  <link name="base_link">
    <visual>
      <origin xyz="0 0 0" rpy="0 0 0"/>
      <geometry>
        <box size="${base_length} ${base_width} ${base_height}"/>
      </geometry>
      <material name="gray"/>
    </visual>

    <collision>
      <origin xyz="0 0 0" rpy="0 0 0"/>
      <geometry>
        <box size="${base_length} ${base_width} ${base_height}"/>
      </geometry>
    </collision>

    <inertial>
      <origin xyz="0 0 0" rpy="0 0 0"/>
      <mass value="5.0"/>
      <inertia
        ixx="0.05" ixy="0.0" ixz="0.0"
        iyy="0.10" iyz="0.0"
        izz="0.10"/>
    </inertial>
  </link>

  <!-- ========================= -->
  <!-- Left wheel -->
  <!-- ========================= -->

  <joint name="left_wheel_joint" type="continuous">
    <parent link="base_link"/>
    <child link="left_wheel_link"/>
    <origin xyz="0 ${wheel_separation / 2.0} ${-base_height / 2.0}" rpy="${-pi/2.0} 0 0"/>
    <axis xyz="0 0 1"/>
  </joint>

  <link name="left_wheel_link">
    <visual>
      <geometry>
        <cylinder radius="${wheel_radius}" length="${wheel_width}"/>
      </geometry>
      <material name="black"/>
    </visual>

    <collision>
      <geometry>
        <cylinder radius="${wheel_radius}" length="${wheel_width}"/>
      </geometry>
    </collision>

    <inertial>
      <mass value="0.5"/>
      <inertia
        ixx="0.001" ixy="0.0" ixz="0.0"
        iyy="0.001" iyz="0.0"
        izz="0.001"/>
    </inertial>
  </link>

  <!-- ========================= -->
  <!-- Right wheel -->
  <!-- ========================= -->

  <joint name="right_wheel_joint" type="continuous">
    <parent link="base_link"/>
    <child link="right_wheel_link"/>
    <origin xyz="0 ${-wheel_separation / 2.0} ${-base_height / 2.0}" rpy="${-pi/2.0} 0 0"/>
    <axis xyz="0 0 1"/>
  </joint>

  <link name="right_wheel_link">
    <visual>
      <geometry>
        <cylinder radius="${wheel_radius}" length="${wheel_width}"/>
      </geometry>
      <material name="black"/>
    </visual>

    <collision>
      <geometry>
        <cylinder radius="${wheel_radius}" length="${wheel_width}"/>
      </geometry>
    </collision>

    <inertial>
      <mass value="0.5"/>
      <inertia
        ixx="0.001" ixy="0.0" ixz="0.0"
        iyy="0.001" iyz="0.0"
        izz="0.001"/>
    </inertial>
  </link>

  <!-- ========================= -->
  <!-- IMU link -->
  <!-- ========================= -->

  <joint name="base_link_to_imu_link" type="fixed">
    <parent link="base_link"/>
    <child link="imu_link"/>
    <origin xyz="0.10 0 0.08" rpy="0 0 0"/>
  </joint>

  <link name="imu_link">
    <visual>
      <origin xyz="0 0 0" rpy="0 0 0"/>
      <geometry>
        <box size="0.04 0.03 0.01"/>
      </geometry>
      <material name="blue"/>
    </visual>

    <collision>
      <geometry>
        <box size="0.04 0.03 0.01"/>
      </geometry>
    </collision>

    <inertial>
      <mass value="0.05"/>
      <inertia
        ixx="0.00001" ixy="0.0" ixz="0.0"
        iyy="0.00001" iyz="0.0"
        izz="0.00001"/>
    </inertial>
  </link>

  <!-- ========================= -->
  <!-- Front direction marker -->
  <!-- ========================= -->

  <joint name="base_link_to_front_marker" type="fixed">
    <parent link="base_link"/>
    <child link="front_marker_link"/>
    <origin xyz="${base_length / 2.0 + 0.03} 0 0.02" rpy="0 0 0"/>
  </joint>

  <link name="front_marker_link">
    <visual>
      <geometry>
        <box size="0.04 0.08 0.04"/>
      </geometry>
      <material name="red"/>
    </visual>
  </link>

</robot>